[2025-01-31T02:49:04.845+0000] {local_task_job_runner.py:123} INFO - ::group::Pre task execution logs
[2025-01-31T02:49:04.866+0000] {taskinstance.py:2612} INFO - Dependencies all met for dep_context=non-requeueable deps ti=<TaskInstance: validate_and_insert_csv_to_postgres_with_branch_adjusted.check_table_branch_task manual__2025-01-31T02:48:58.395068+00:00 [queued]>
[2025-01-31T02:49:04.877+0000] {taskinstance.py:2612} INFO - Dependencies all met for dep_context=requeueable deps ti=<TaskInstance: validate_and_insert_csv_to_postgres_with_branch_adjusted.check_table_branch_task manual__2025-01-31T02:48:58.395068+00:00 [queued]>
[2025-01-31T02:49:04.879+0000] {taskinstance.py:2865} INFO - Starting attempt 1 of 1
[2025-01-31T02:49:04.903+0000] {taskinstance.py:2888} INFO - Executing <Task(BranchPythonOperator): check_table_branch_task> on 2025-01-31 02:48:58.395068+00:00
[2025-01-31T02:49:04.915+0000] {warnings.py:112} WARNING - /home/***/.local/lib/python3.12/site-packages/***/task/task_runner/standard_task_runner.py:70: DeprecationWarning: This process (pid=80) is multi-threaded, use of fork() may lead to deadlocks in the child.
  pid = os.fork()

[2025-01-31T02:49:04.918+0000] {standard_task_runner.py:72} INFO - Started process 82 to run task
[2025-01-31T02:49:04.920+0000] {standard_task_runner.py:104} INFO - Running: ['***', 'tasks', 'run', 'validate_and_insert_csv_to_postgres_with_branch_adjusted', 'check_table_branch_task', 'manual__2025-01-31T02:48:58.395068+00:00', '--job-id', '3', '--raw', '--subdir', 'DAGS_FOLDER/read_file_updated.py', '--cfg-path', '/tmp/tmpjerf1j9n']
[2025-01-31T02:49:04.921+0000] {standard_task_runner.py:105} INFO - Job 3: Subtask check_table_branch_task
[2025-01-31T02:49:04.990+0000] {task_command.py:467} INFO - Running <TaskInstance: validate_and_insert_csv_to_postgres_with_branch_adjusted.check_table_branch_task manual__2025-01-31T02:48:58.395068+00:00 [running]> on host e2498a6c8083
[2025-01-31T02:49:05.106+0000] {taskinstance.py:3131} INFO - Exporting env vars: AIRFLOW_CTX_DAG_OWNER='***' AIRFLOW_CTX_DAG_ID='validate_and_insert_csv_to_postgres_with_branch_adjusted' AIRFLOW_CTX_TASK_ID='check_table_branch_task' AIRFLOW_CTX_EXECUTION_DATE='2025-01-31T02:48:58.395068+00:00' AIRFLOW_CTX_TRY_NUMBER='1' AIRFLOW_CTX_DAG_RUN_ID='manual__2025-01-31T02:48:58.395068+00:00'
[2025-01-31T02:49:05.110+0000] {logging_mixin.py:190} INFO - Task instance is in running state
[2025-01-31T02:49:05.111+0000] {logging_mixin.py:190} INFO -  Previous state of the Task instance: queued
[2025-01-31T02:49:05.112+0000] {logging_mixin.py:190} INFO - Current task name:check_table_branch_task state:running start_date:2025-01-31 02:49:04.867473+00:00
[2025-01-31T02:49:05.113+0000] {logging_mixin.py:190} INFO - Dag name:validate_and_insert_csv_to_postgres_with_branch_adjusted and current dag run status:running
[2025-01-31T02:49:05.114+0000] {taskinstance.py:731} INFO - ::endgroup::
[2025-01-31T02:49:05.116+0000] {baseoperator.py:405} WARNING - BranchPythonOperator.execute cannot be called outside TaskInstance!
[2025-01-31T02:49:05.158+0000] {taskinstance.py:3310} ERROR - Task failed with exception
Traceback (most recent call last):
  File "/home/airflow/.local/lib/python3.12/site-packages/airflow/models/taskinstance.py", line 767, in _execute_task
    result = _execute_callable(context=context, **execute_callable_kwargs)
             ^^^^^^^^^^^^^^^^^^^^^^^^^^^^^^^^^^^^^^^^^^^^^^^^^^^^^^^^^^^^^
  File "/home/airflow/.local/lib/python3.12/site-packages/airflow/models/taskinstance.py", line 733, in _execute_callable
    return ExecutionCallableRunner(
           ^^^^^^^^^^^^^^^^^^^^^^^^
  File "/home/airflow/.local/lib/python3.12/site-packages/airflow/utils/operator_helpers.py", line 252, in run
    return self.func(*args, **kwargs)
           ^^^^^^^^^^^^^^^^^^^^^^^^^^
  File "/home/airflow/.local/lib/python3.12/site-packages/airflow/models/baseoperator.py", line 406, in wrapper
    return func(self, *args, **kwargs)
           ^^^^^^^^^^^^^^^^^^^^^^^^^^^
  File "/home/airflow/.local/lib/python3.12/site-packages/airflow/operators/python.py", line 274, in execute
    return self.do_branch(context, super().execute(context))
                                   ^^^^^^^^^^^^^^^^^^^^^^^^
  File "/home/airflow/.local/lib/python3.12/site-packages/airflow/models/baseoperator.py", line 406, in wrapper
    return func(self, *args, **kwargs)
           ^^^^^^^^^^^^^^^^^^^^^^^^^^^
  File "/home/airflow/.local/lib/python3.12/site-packages/airflow/operators/python.py", line 238, in execute
    return_value = self.execute_callable()
                   ^^^^^^^^^^^^^^^^^^^^^^^
  File "/home/airflow/.local/lib/python3.12/site-packages/airflow/operators/python.py", line 256, in execute_callable
    return runner.run(*self.op_args, **self.op_kwargs)
           ^^^^^^^^^^^^^^^^^^^^^^^^^^^^^^^^^^^^^^^^^^^
  File "/home/airflow/.local/lib/python3.12/site-packages/airflow/utils/operator_helpers.py", line 252, in run
    return self.func(*args, **kwargs)
           ^^^^^^^^^^^^^^^^^^^^^^^^^^
  File "/opt/airflow/dags/read_file_updated.py", line 25, in check_table_branch
    with hook.get_conn() as conn:
         ^^^^^^^^^^^^^^^
  File "/home/airflow/.local/lib/python3.12/site-packages/airflow/providers/postgres/hooks/postgres.py", line 146, in get_conn
    conn = deepcopy(self.connection or self.get_connection(conn_id))
                                       ^^^^^^^^^^^^^^^^^^^^^^^^^^^^
  File "/home/airflow/.local/lib/python3.12/site-packages/airflow/hooks/base.py", line 83, in get_connection
    conn = Connection.get_connection_from_secrets(conn_id)
           ^^^^^^^^^^^^^^^^^^^^^^^^^^^^^^^^^^^^^^^^^^^^^^^
  File "/home/airflow/.local/lib/python3.12/site-packages/airflow/models/connection.py", line 537, in get_connection_from_secrets
    raise AirflowNotFoundException(f"The conn_id `{conn_id}` isn't defined")
airflow.exceptions.AirflowNotFoundException: The conn_id `postgres_default` isn't defined
[2025-01-31T02:49:05.185+0000] {logging_mixin.py:190} INFO - Task instance in failure state
[2025-01-31T02:49:05.186+0000] {logging_mixin.py:190} INFO - Task start:2025-01-31 02:49:04.867473+00:00 end:2025-01-31 02:49:05.184456+00:00 duration:0.316983
[2025-01-31T02:49:05.187+0000] {logging_mixin.py:190} INFO - Task:<Task(BranchPythonOperator): check_table_branch_task> dag:<DAG: validate_and_insert_csv_to_postgres_with_branch_adjusted> dagrun:<DagRun validate_and_insert_csv_to_postgres_with_branch_adjusted @ 2025-01-31 02:48:58.395068+00:00: manual__2025-01-31T02:48:58.395068+00:00, state:running, queued_at: 2025-01-31 02:48:58.418274+00:00. externally triggered: True>
[2025-01-31T02:49:05.188+0000] {logging_mixin.py:190} INFO - Failure caused by The conn_id `postgres_default` isn't defined
[2025-01-31T02:49:05.190+0000] {taskinstance.py:1225} INFO - Marking task as FAILED. dag_id=validate_and_insert_csv_to_postgres_with_branch_adjusted, task_id=check_table_branch_task, run_id=manual__2025-01-31T02:48:58.395068+00:00, execution_date=20250131T024858, start_date=20250131T024904, end_date=20250131T024905
[2025-01-31T02:49:05.218+0000] {taskinstance.py:340} INFO - ::group::Post task execution logs
[2025-01-31T02:49:05.221+0000] {standard_task_runner.py:124} ERROR - Failed to execute job 3 for task check_table_branch_task (The conn_id `postgres_default` isn't defined; 82)
Traceback (most recent call last):
  File "/home/airflow/.local/lib/python3.12/site-packages/airflow/task/task_runner/standard_task_runner.py", line 117, in _start_by_fork
    ret = args.func(args, dag=self.dag)
          ^^^^^^^^^^^^^^^^^^^^^^^^^^^^^
  File "/home/airflow/.local/lib/python3.12/site-packages/airflow/cli/cli_config.py", line 49, in command
    return func(*args, **kwargs)
           ^^^^^^^^^^^^^^^^^^^^^
  File "/home/airflow/.local/lib/python3.12/site-packages/airflow/utils/cli.py", line 115, in wrapper
    return f(*args, **kwargs)
           ^^^^^^^^^^^^^^^^^^
  File "/home/airflow/.local/lib/python3.12/site-packages/airflow/cli/commands/task_command.py", line 483, in task_run
    task_return_code = _run_task_by_selected_method(args, _dag, ti)
                       ^^^^^^^^^^^^^^^^^^^^^^^^^^^^^^^^^^^^^^^^^^^^
  File "/home/airflow/.local/lib/python3.12/site-packages/airflow/cli/commands/task_command.py", line 256, in _run_task_by_selected_method
    return _run_raw_task(args, ti)
           ^^^^^^^^^^^^^^^^^^^^^^^
  File "/home/airflow/.local/lib/python3.12/site-packages/airflow/cli/commands/task_command.py", line 341, in _run_raw_task
    return ti._run_raw_task(
           ^^^^^^^^^^^^^^^^^
  File "/home/airflow/.local/lib/python3.12/site-packages/airflow/utils/session.py", line 97, in wrapper
    return func(*args, session=session, **kwargs)
           ^^^^^^^^^^^^^^^^^^^^^^^^^^^^^^^^^^^^^^
  File "/home/airflow/.local/lib/python3.12/site-packages/airflow/models/taskinstance.py", line 3004, in _run_raw_task
    return _run_raw_task(
           ^^^^^^^^^^^^^^
  File "/home/airflow/.local/lib/python3.12/site-packages/airflow/models/taskinstance.py", line 273, in _run_raw_task
    TaskInstance._execute_task_with_callbacks(
  File "/home/airflow/.local/lib/python3.12/site-packages/airflow/models/taskinstance.py", line 3158, in _execute_task_with_callbacks
    result = self._execute_task(context, task_orig)
             ^^^^^^^^^^^^^^^^^^^^^^^^^^^^^^^^^^^^^^
  File "/home/airflow/.local/lib/python3.12/site-packages/airflow/models/taskinstance.py", line 3182, in _execute_task
    return _execute_task(self, context, task_orig)
           ^^^^^^^^^^^^^^^^^^^^^^^^^^^^^^^^^^^^^^^
  File "/home/airflow/.local/lib/python3.12/site-packages/airflow/models/taskinstance.py", line 767, in _execute_task
    result = _execute_callable(context=context, **execute_callable_kwargs)
             ^^^^^^^^^^^^^^^^^^^^^^^^^^^^^^^^^^^^^^^^^^^^^^^^^^^^^^^^^^^^^
  File "/home/airflow/.local/lib/python3.12/site-packages/airflow/models/taskinstance.py", line 733, in _execute_callable
    return ExecutionCallableRunner(
           ^^^^^^^^^^^^^^^^^^^^^^^^
  File "/home/airflow/.local/lib/python3.12/site-packages/airflow/utils/operator_helpers.py", line 252, in run
    return self.func(*args, **kwargs)
           ^^^^^^^^^^^^^^^^^^^^^^^^^^
  File "/home/airflow/.local/lib/python3.12/site-packages/airflow/models/baseoperator.py", line 406, in wrapper
    return func(self, *args, **kwargs)
           ^^^^^^^^^^^^^^^^^^^^^^^^^^^
  File "/home/airflow/.local/lib/python3.12/site-packages/airflow/operators/python.py", line 274, in execute
    return self.do_branch(context, super().execute(context))
                                   ^^^^^^^^^^^^^^^^^^^^^^^^
  File "/home/airflow/.local/lib/python3.12/site-packages/airflow/models/baseoperator.py", line 406, in wrapper
    return func(self, *args, **kwargs)
           ^^^^^^^^^^^^^^^^^^^^^^^^^^^
  File "/home/airflow/.local/lib/python3.12/site-packages/airflow/operators/python.py", line 238, in execute
    return_value = self.execute_callable()
                   ^^^^^^^^^^^^^^^^^^^^^^^
  File "/home/airflow/.local/lib/python3.12/site-packages/airflow/operators/python.py", line 256, in execute_callable
    return runner.run(*self.op_args, **self.op_kwargs)
           ^^^^^^^^^^^^^^^^^^^^^^^^^^^^^^^^^^^^^^^^^^^
  File "/home/airflow/.local/lib/python3.12/site-packages/airflow/utils/operator_helpers.py", line 252, in run
    return self.func(*args, **kwargs)
           ^^^^^^^^^^^^^^^^^^^^^^^^^^
  File "/opt/airflow/dags/read_file_updated.py", line 25, in check_table_branch
    with hook.get_conn() as conn:
         ^^^^^^^^^^^^^^^
  File "/home/airflow/.local/lib/python3.12/site-packages/airflow/providers/postgres/hooks/postgres.py", line 146, in get_conn
    conn = deepcopy(self.connection or self.get_connection(conn_id))
                                       ^^^^^^^^^^^^^^^^^^^^^^^^^^^^
  File "/home/airflow/.local/lib/python3.12/site-packages/airflow/hooks/base.py", line 83, in get_connection
    conn = Connection.get_connection_from_secrets(conn_id)
           ^^^^^^^^^^^^^^^^^^^^^^^^^^^^^^^^^^^^^^^^^^^^^^^
  File "/home/airflow/.local/lib/python3.12/site-packages/airflow/models/connection.py", line 537, in get_connection_from_secrets
    raise AirflowNotFoundException(f"The conn_id `{conn_id}` isn't defined")
airflow.exceptions.AirflowNotFoundException: The conn_id `postgres_default` isn't defined
[2025-01-31T02:49:05.259+0000] {local_task_job_runner.py:266} INFO - Task exited with return code 1
[2025-01-31T02:49:05.309+0000] {taskinstance.py:3900} INFO - 0 downstream tasks scheduled from follow-on schedule check
[2025-01-31T02:49:05.321+0000] {local_task_job_runner.py:245} INFO - ::endgroup::
